Workbook

Sheet 使用说明
A1: 事项 | B1: 说明
A2: 研究状态 | B2: 2025养老金三类金额齐全2县，人数也齐全1县；两县养老金来源均为转载，不能外推全省。
A3: 快照审计 | B3: 成功归档15/16个登记URL；数值定位不等于口径核实。详见来源快照与逐条审计。
A4: 公式 | B4: 养老金月均代理=全年发放万元×10000÷年末领取人数÷12；非实际人均月待遇。
A5: 复现 | B5: python scripts/prepare_data.py; python scripts/reproduce.py; python scripts/audit_snapshots.py; python scripts/build_audited_workbook.py
A6: 旧版数据 | B6: 上一版基础数据库.xlsx保留作线索，未逐条核验的数据不进入本工作簿事实层。
A7: 资金边界 | B7: 社保基金、一般公共预算、住房公积金分别核算；禁止跨账相减。

Sheet 行政区100
A1: region_code | B1: province | C1: prefecture | D1: county | E1: type | F1: code_reference | G1: code_reference_year | H1: verified_for_2025
A2: 360102 | B2: 江西省 | C2: 南昌市 | D2: 东湖区 | E2: 区 | F2: https://www.zxinc.org/gb2260-2024.htm | G2: 2024-12-31 | H2: 2025年末官方代码待最终逐项核对
A3: 360103 | B3: 江西省 | C3: 南昌市 | D3: 西湖区 | E3: 区 | F3: https://www.zxinc.org/gb2260-2024.htm | G3: 2024-12-31 | H3: 2025年末官方代码待最终逐项核对
A4: 360104 | B4: 江西省 | C4: 南昌市 | D4: 青云谱区 | E4: 区 | F4: https://www.zxinc.org/gb2260-2024.htm | G4: 2024-12-31 | H4: 2025年末官方代码待最终逐项核对
A5: 360111 | B5: 江西省 | C5: 南昌市 | D5: 青山湖区 | E5: 区 | F5: https://www.zxinc.org/gb2260-2024.htm | G5: 2024-12-31 | H5: 2025年末官方代码待最终逐项核对
A6: 360112 | B6: 江西省 | C6: 南昌市 | D6: 新建区 | E6: 区 | F6: https://www.zxinc.org/gb2260-2024.htm | G6: 2024-12-31 | H6: 2025年末官方代码待最终逐项核对
A7: 360113 | B7: 江西省 | C7: 南昌市 | D7: 红谷滩区 | E7: 区 | F7: https://www.zxinc.org/gb2260-2024.htm | G7: 2024-12-31 | H7: 2025年末官方代码待最终逐项核对
A8: 360121 | B8: 江西省 | C8: 南昌市 | D8: 南昌县 | E8: 县 | F8: https://www.zxinc.org/gb2260-2024.htm | G8: 2024-12-31 | H8: 2025年末官方代码待最终逐项核对
A9: 360123 | B9: 江西省 | C9: 南昌市 | D9: 安义县 | E9: 县 | F9: https://www.zxinc.org/gb2260-2024.htm | G9: 2024-12-31 | H9: 2025年末官方代码待最终逐项核对
A10: 360124 | B10: 江西省 | C10: 南昌市 | D10: 进贤县 | E10: 县 | F10: https://www.zxinc.org/gb2260-2024.htm | G10: 2024-12-31 | H10: 2025年末官方代码待最终逐项核对
A11: 360202 | B11: 江西省 | C11: 景德镇市 | D11: 昌江区 | E11: 区 | F11: https://www.zxinc.org/gb2260-2024.htm | G11: 2024-12-31 | H11: 2025年末官方代码待最终逐项核对
A12: 360203 | B12: 江西省 | C12: 景德镇市 | D12: 珠山区 | E12: 区 | F12: https://www.zxinc.org/gb2260-2024.htm | G12: 2024-12-31 | H12: 2025年末官方代码待最终逐项核对
... A101: 361130 | B101: 江西省 | C101: 上饶市 | D101: 婺源县 | E101: 县 | F101: https://www.zxinc.org/gb2260-2024.htm | G101: 2024-12-31 | H101: 2025年末官方代码待最终逐项核对

Sheet 来源索引
A1: source_id | B1: title | C1: publisher | D1: geography | E1: observation_year | F1: source_type | G1: url | H1: grade | I1: locator | J1: publication_date | K1: caveat
A2: S01 | B2: 江西省2025年国民经济和社会发展统计公报 | C2: 江西省统计局、国家统计局江西调查总队 | D2: 江西省 | E2: 2025 | F2: 官方公报刊载 | G2: https://epaper.jxxw.com.cn/html/2026-03/27/content_7_88438.htm | H2: A-官方发布渠道 | I2: 综合、就业、社保章节 | J2: 2026-03-27 | K2: 报纸网页已封存；分项统计口径仍需逐项核对
A3: S02 | B3: 峡江县2025年国民经济和社会发展统计公报 | C3: 署名峡江县统计局 | D3: 峡江县 | E3: 2025 | F3: 第三方统计公报转载 | G3: https://tjgb.hongheiku.com/xjtjgb/xj2020/73609.html | H3: B-原文转载待官方终核 | I3: 十、人口就业、人民生活和社会保障 | J3: 2026-06-07 | K3: 尚未取得可访问的2025县政府原文；数据为年度快报
A4: S03 | B4: 峡江县2024年国民经济和社会发展统计公报 | C4: 署名峡江县统计局 | D4: 峡江县 | E4: 2024 | F4: 第三方转载＋官方搜索摘要 | G4: https://tjgb.hongheiku.com/xjtjgb/xj2020/65339.html | H4: B-转载/局部官方确认 | I4: 十、人口就业、人民生活和社会保障 | J4: 2025-07-09 | K4: 县政府2024版本链接 https://m.xiajiang.gov.cn/news-show-52834.html 访问超时
A5: S04 | B5: 吉安县2025年国民经济和社会发展统计公报 | C5: 署名吉安县相关统计部门 | D5: 吉安县 | E5: 2025 | F5: 第三方平台公报全文 | G5: https://maptable.com/tjgb/2025/%E5%90%89%E5%AE%89%E5%B8%82/%E5%90%89%E5%AE%89%E5%8E%BF/report/ji-an-shi-ji-an-xian-2025-nian-guo-min-jing-ji-he-she-hui-fa-zhan-tong-ji-gong-bao | H5: B-原文转载待官方终核 | I5: 九、人民生活与社会保障 | J5: 2026 | K5: 未找到县政府原始发布全文；只有养老金金额、无分制度待遇领取人数
A6: S05 | B6: 2025年赣州常住人口总量总体稳定 城镇化率突破60% | C6: 赣州市统计局 | D6: 赣州市及分县 | E6: 2025 | F6: 市政府官网原文 | G6: https://www.ganzhou.gov.cn/zfxxgk/tjzdtjfx/202605/1b10c9c94cf1443f851d6523be5863d3.shtml | H6: A-政府原始发布 | I6: 正文与各县常住人口表 | J6: 2026-05-14 | K6: 含20个统计片区，县级建制18个；功能区不得混入行政区合计
A7: S06 | B7: 赣州2024年各县（市、区）常住人口主要指标 | C7: 赣州市统计局 | D7: 赣州市及分县 | E7: 2024 | F7: 市政府官网原文 | G7: https://www.ganzhou.gov.cn/zfxxgk/c100093n1/202503/c7bfdc7911ac4c898c559e58a215509a.shtml | H7: A-政府原始发布 | I7: 常住人口、性别比、城镇化率表 | J7: 2025-03-22 | K7: 人口以万人两位小数发布，增量含舍入误差
A8: S07 | B8: 石城县2025年国民经济和社会发展统计公报 | C8: 石城县统计局 | D8: 石城县 | E8: 2025 | F8: 县政府官网原文 | G8: https://www.shicheng.gov.cn/scxxxgk/tjgb/202604/adc5c0bf738b43f3b5b80a2693d08ed4.shtml | H8: A-政府原始发布 | I8: 一、综合；九、人口、人民生活、社会保障 | J8: 2026-04-21 | K8: 60岁及以上人数是户籍人口口径；不得除以常住人口
A9: S08 | B9: 江西省住房公积金2025年年度报告 | C9: 江西省住房和城乡建设厅 | D9: 江西省/设区市 | E9: 2025 | F9: 省住建厅原始通知及官方内容转载 | G9: https://zjt.jiangxi.gov.cn/jxszfhcxjst/wjtz/pc/content/content_2049308288025104384.html | H9: A-主管部门发布/可检索 | I9: 二、业务运行情况：缴存、提取、贷款 | J9: 2026-04-30 | K9: 市级表格来自既有工作簿，须对照官方图片逐行最终核验
A10: S09 | B10: 江西省2025年全省和省级预算执行情况与2026年预算草案报告 | C10: 江西省财政厅 | D10: 江西省全省/省级 | E10: 2025执行 | F10: 省人大会议文件（江西日报） | G10: https://jiangxi.jxnews.com.cn/system/2026/02/09/031051192.shtml | H10: A-政府预算报告 | I10: 2025全省与省级社会保险基金预算执行 | J10: 2026-02-09 | K10: 全省与省级分开，不是仅基本养老金
A11: S10 | B11: 江西省2025年省级决算和2026年上半年预算执行情况报告 | C11: 江西省人民政府、省人大新闻 | D11: 江西省省级 | E11: 2025决算 | F11: 人大网站公报 | G11: https://jxrd.jxnews.com.cn/system/2026/08/11/031215391.shtml | H11: A-人大公报 | I11: 2025省级社保基金预算决算 | J11: 2026-08-11 | K11: 省级决算不得与全省执行混合或加总
A12: S11 | B12: 江西省2025年平均工资公布 | C12: 江西省统计局(江西统计)；赣江新区官网转载 | D12: 江西省 | E12: 2025 | F12: 政府网页转载主管部门发布 | G12: https://www.jdzzsq.gov.cn/qrsj/qtfdgkxx/gzdt/t1095997.shtml | H12: A-政府系统转载 | I12: 城镇非私营与私营就业人员工资 | J12: 2026-06-26 | K12: 不同单位类型、样本构成；不能当同职业待遇差异
... A17: S16 | B17: 江西省行政区划（2025年） | C17: 区划地名网 | D17: 江西省 | E17: 2025 | F17: 第三方按年度行政名录 | G17: https://xzqh.org/show/china/36/2025.html | H17: B-行政区划二手索引 | I17: 2025末11市100县级单位 | J17: 2025 | K17: 2025数目与既有100县表相符；民政部为最终编码源

Sheet 来源快照
A1: source_id | B1: retrieved_at_utc | C1: requested_url | D1: final_url | E1: http_status | F1: content_type | G1: path | H1: sha256 | I1: bytes | J1: error
A2: S01 | B2: 2026-10-27T08:12:31+00:00 | C2: https://epaper.jxxw.com.cn/html/2026-03/27/content_7_88438.htm | D2: https://epaper.jxxw.com.cn/html/2026-03/27/content_7_88438.htm | E2: 200 | F2: text/html | G2: data/source_snapshots/S01.html | H2: c66c9d5bf22e6369074d3d5433fbe08111b6cade7fadeba6e3d511279ed348cc | I2: 98526
A3: S02 | B3: 2026-10-27T08:12:31+00:00 | C3: https://tjgb.hongheiku.com/xjtjgb/xj2020/73609.html | D3: https://tjgb.hongheiku.com/xjtjgb/xj2020/73609.html | E3: 200 | F3: text/html; charset=UTF-8 | G3: data/source_snapshots/S02.html | H3: 5b10922df52b52fc1a3fad982ab538c4c4d67ffef3d859ef188f0232e392d0e7 | I3: 39072
A4: S03 | B4: 2026-10-27T08:12:31+00:00 | C4: https://tjgb.hongheiku.com/xjtjgb/xj2020/65339.html | D4: https://tjgb.hongheiku.com/xjtjgb/xj2020/65339.html | E4: 200 | F4: text/html; charset=UTF-8 | G4: data/source_snapshots/S03.html | H4: 5a7b217e14a5e5cd78ad5fe84bdcbc95e4e865e5a4dcbf032c4b6e0ebafcab42 | I4: 38464
A5: S04 | B5: 2026-10-27T08:12:31+00:00 | C5: https://maptable.com/tjgb/2025/%E5%90%89%E5%AE%89%E5%B8%82/%E5%90%89%E5%AE%89%E5%8E%BF/report/ji-an-shi-ji-an-xian-2025-nian-guo-min-jing-ji-he-she-hui-fa-zhan-tong-ji-gong-bao | D5: https://maptable.com/tjgb/2025/%E5%90%89%E5%AE%89%E5%B8%82/%E5%90%89%E5%AE%89%E5%8E%BF/report/ji-an-shi-ji-an-xian-2025-nian-guo-min-jing-ji-he-she-hui-fa-zhan-tong-ji-gong-bao | E5: 200 | F5: text/html; charset=utf-8 | G5: data/source_snapshots/S04.html | H5: 0b098126f1d4f8d966f8ab47d99d5f1f7577a475b5f222d3390bf61176c32b01 | I5: 30509
A6: S05 | B6: 2026-10-27T08:12:32+00:00 | C6: https://www.ganzhou.gov.cn/zfxxgk/tjzdtjfx/202605/1b10c9c94cf1443f851d6523be5863d3.shtml | D6: https://www.ganzhou.gov.cn/zfxxgk/tjzdtjfx/202605/1b10c9c94cf1443f851d6523be5863d3.shtml | E6: 200 | F6: text/html | G6: data/source_snapshots/S05.html | H6: d946a7a33e097676c1722dbead1b8f957b9138701f496b6d3e006a820f64420a | I6: 60852
A7: S06 | B7: 2026-10-27T08:12:32+00:00 | C7: https://www.ganzhou.gov.cn/zfxxgk/c100093n1/202503/c7bfdc7911ac4c898c559e58a215509a.shtml | D7: https://www.ganzhou.gov.cn/zfxxgk/c100093n1/202503/c7bfdc7911ac4c898c559e58a215509a.shtml | E7: 200 | F7: text/html | G7: data/source_snapshots/S06.html | H7: a6be1e1c39cedd3e71867cc93f3948b44b942055e9836114124acc95ff037289 | I7: 59461
A8: S07 | B8: 2026-10-27T08:12:32+00:00 | C8: https://www.shicheng.gov.cn/scxxxgk/tjgb/202604/adc5c0bf738b43f3b5b80a2693d08ed4.shtml | D8: https://www.shicheng.gov.cn/scxxxgk/tjgb/202604/adc5c0bf738b43f3b5b80a2693d08ed4.shtml | E8: 200 | F8: text/html; charset=utf-8 | G8: data/source_snapshots/S07.html | H8: a490422fd429eeb1dbc2450f4f14e1785ec940e8e920b6d54cb639fe23278ba6 | I8: 186370
A9: S08 | B9: 2026-10-27T08:12:32+00:00 | C9: https://zjt.jiangxi.gov.cn/jxszfhcxjst/wjtz/pc/content/content_2049308288025104384.html | J9: SSLError: HTTPSConnectionPool(host='zjt.jiangxi.gov.cn', port=443): Max retries exceeded with url: /jxszfhcxjst/wjtz/pc/content/content_2049308288025104384.html (Caused by SSLError(SSLError(1, '[SSL: UNSAFE_LEGACY_RENEGOTIATION_DISABLED] unsafe legacy renegotiation disabled (_ssl.c:1007)')))
A10: S09 | B10: 2026-10-27T08:12:32+00:00 | C10: https://jiangxi.jxnews.com.cn/system/2026/02/09/031051192.shtml | D10: https://jiangxi.jxnews.com.cn/system/2026/02/09/031051192.shtml | E10: 200 | F10: text/html | G10: data/source_snapshots/S09.html | H10: 70d60f9cedd307b8a4e6ecbb6764eab791cca1b2e68233cf3a256d406bbda2bd | I10: 65406
A11: S10 | B11: 2026-10-27T08:12:32+00:00 | C11: https://jxrd.jxnews.com.cn/system/2026/08/11/031215391.shtml | D11: https://jxrd.jxnews.com.cn/system/2026/08/11/031215391.shtml | E11: 200 | F11: text/html | G11: data/source_snapshots/S10.html | H11: a2bc6c1bffc2931a56300cfd94c366503a28e4f08f54390197449ed9ebd1f325 | I11: 25087
A12: S11 | B12: 2026-10-27T08:12:32+00:00 | C12: https://www.jdzzsq.gov.cn/qrsj/qtfdgkxx/gzdt/t1095997.shtml | D12: https://www.jdzzsq.gov.cn/qrsj/qtfdgkxx/gzdt/t1095997.shtml | E12: 200 | F12: text/html | G12: data/source_snapshots/S11.html | H12: 0ef080dd034000f6e1e2ae9c1d6e109ec6bfa991a25a1763e8d2726ae9a11e6f | I12: 74189
A13: S12 | B13: 2026-10-27T08:12:36+00:00 | C13: https://www.zxinc.org/gb2260-2024.htm | D13: https://www.zxinc.org/gb2260-2024.htm | E13: 200 | F13: text/html | G13: data/source_snapshots/S12.html | H13: 2aac5477364c4ce9d51b409386e422f484659ca51673c3907bdb3bbcb0f22cf8 | I13: 111074
A14: S13 | B14: 2026-10-27T08:12:37+00:00 | C14: https://jx.mof.gov.cn/xxgk/tongzhitonggao/202507/t20250728_3968859.htm | D14: https://jx.mof.gov.cn/xxgk/tongzhitonggao/202507/t20250728_3968859.htm | E14: 200 | F14: text/html | G14: data/source_snapshots/S13.html | H14: 7347338ad35f294ffd5f295bfb287bbeccf26452bcdac476742f2c4a50901e01 | I14: 14543
A15: S14 | B15: 2026-10-27T08:12:37+00:00 | C15: https://www.stats.gov.cn/sj/zxfbhjd/202602/t20260228_1962662.html | D15: https://www.stats.gov.cn/sj/zxfbhjd/202602/t20260228_1962662.html | E15: 200 | F15: text/html | G15: data/source_snapshots/S14.html | H15: 08da28a6c88328c324e04038911f24f9d66415c6db1893fc0fd9d8f5a6adc721 | I15: 1118852
A16: S15 | B16: 2026-10-27T08:12:39+00:00 | C16: https://jx.ifeng.com/c/8sk35lBJNwe | D16: https://jx.ifeng.com/c/8sk35lBJNwe | E16: 200 | F16: text/html; charset=utf-8 | G16: data/source_snapshots/S15.html | H16: 887b3e45ece9da578930c2a2980304f56c4139fde1ee981ca0c79857da1209e6 | I16: 45583
A17: S16 | B17: 2026-10-27T08:12:39+00:00 | C17: https://xzqh.org/show/china/36/2025.html | D17: https://xzqh.org/show/china/36/2025.html | E17: 200 | F17: text/html | G17: data/source_snapshots/S16.html | H17: b0b89bbb665ff3f92f88371169d5907b0fc08c5e447f59de7714b4fe6afcc225 | I17: 6868

Sheet 事实142条
A1: region_code | B1: region_name | C1: level | D1: year | E1: indicator_id | F1: value | G1: unit | H1: population_scope | I1: source_id | J1: verification_status | K1: snapshot_status | L1: page_number | M1: caveat | N1: source_version
A2: 360823 | B2: 峡江县 | C2: 县 | D2: 2024 | E2: pension_enterprise_recipients_year_end | F2: 10779 | G2: 人 | H2: enterprise | I2: S03 | J2: B_转载待官方核 | K2: 归档状态与SHA-256见source_snapshot_manifest.csv；口径核实见source_number_audit.csv | M2: 年末人数，非全年平均领取人数 | N2: S03
A3: 360823 | B3: 峡江县 | C3: 县 | D3: 2024 | E3: pension_enterprise_annual_paid | F3: 26955.46 | G3: 万元 | H3: enterprise | I3: S03 | J3: B_转载待官方核 | K3: 归档状态与SHA-256见source_snapshot_manifest.csv；口径核实见source_number_audit.csv | M3: 2025初步快报，资金发放口径待专项核对 | N3: S03
A4: 360823 | B4: 峡江县 | C4: 县 | D4: 2024 | E4: pension_enterprise_active_or_paid | F4: 24495 | G4: 人 | H4: enterprise | I4: S03 | J4: B_转载待官方核 | K4: 归档状态与SHA-256见source_snapshot_manifest.csv；口径核实见source_number_audit.csv | M4: 职工在职参保/城乡居民实际缴费不同口径 | N4: S03
A5: 360823 | B5: 峡江县 | C5: 县 | D5: 2024 | E5: pension_enterprise_contribution | F5: 18642.9 | G5: 万元 | H5: enterprise | I5: S03 | J5: B_转载待官方核 | K5: 归档状态与SHA-256见source_snapshot_manifest.csv；口径核实见source_number_audit.csv | M5: 征缴基金，不等于同一县域待遇支付的全部资金来源 | N5: S03
A6: 360823 | B6: 峡江县 | C6: 县 | D6: 2024 | E6: pension_public_recipients_year_end | F6: 2453 | G6: 人 | H6: public | I6: S03 | J6: B_转载待官方核 | K6: 归档状态与SHA-256见source_snapshot_manifest.csv；口径核实见source_number_audit.csv | M6: 年末人数，非全年平均领取人数 | N6: S03
A7: 360823 | B7: 峡江县 | C7: 县 | D7: 2024 | E7: pension_public_annual_paid | F7: 15209.48 | G7: 万元 | H7: public | I7: S03 | J7: B_转载待官方核 | K7: 归档状态与SHA-256见source_snapshot_manifest.csv；口径核实见source_number_audit.csv | M7: 2025初步快报，资金发放口径待专项核对 | N7: S03
A8: 360823 | B8: 峡江县 | C8: 县 | D8: 2024 | E8: pension_public_active_or_paid | F8: 4977 | G8: 人 | H8: public | I8: S03 | J8: B_转载待官方核 | K8: 归档状态与SHA-256见source_snapshot_manifest.csv；口径核实见source_number_audit.csv | M8: 职工在职参保/城乡居民实际缴费不同口径 | N8: S03
A9: 360823 | B9: 峡江县 | C9: 县 | D9: 2024 | E9: pension_public_contribution | F9: 11378.18 | G9: 万元 | H9: public | I9: S03 | J9: B_转载待官方核 | K9: 归档状态与SHA-256见source_snapshot_manifest.csv；口径核实见source_number_audit.csv | M9: 征缴基金，不等于同一县域待遇支付的全部资金来源 | N9: S03
A10: 360823 | B10: 峡江县 | C10: 县 | D10: 2024 | E10: pension_resident_recipients_year_end | F10: 25995 | G10: 人 | H10: resident | I10: S03 | J10: B_转载待官方核 | K10: 归档状态与SHA-256见source_snapshot_manifest.csv；口径核实见source_number_audit.csv | M10: 年末人数，非全年平均领取人数 | N10: S03
A11: 360823 | B11: 峡江县 | C11: 县 | D11: 2024 | E11: pension_resident_annual_paid | F11: 5975.44 | G11: 万元 | H11: resident | I11: S03 | J11: B_转载待官方核 | K11: 归档状态与SHA-256见source_snapshot_manifest.csv；口径核实见source_number_audit.csv | M11: 2025初步快报，资金发放口径待专项核对 | N11: S03
A12: 360823 | B12: 峡江县 | C12: 县 | D12: 2024 | E12: pension_resident_active_or_paid | F12: 33989 | G12: 人 | H12: resident | I12: S03 | J12: B_转载待官方核 | K12: 归档状态与SHA-256见source_snapshot_manifest.csv；口径核实见source_number_audit.csv | M12: 职工在职参保/城乡居民实际缴费不同口径 | N12: S03
A13: 360823 | B13: 峡江县 | C13: 县 | D13: 2024 | E13: pension_resident_contribution | F13: 4208.58 | G13: 万元 | H13: resident | I13: S03 | J13: B_转载待官方核 | K13: 归档状态与SHA-256见source_snapshot_manifest.csv；口径核实见source_number_audit.csv | M13: 征缴基金，不等于同一县域待遇支付的全部资金来源 | N13: S03
... A25: 360823 | B25: 峡江县 | C25: 县 | D25: 2025 | E25: pension_resident_contribution | F25: 5134.06 | G25: 万元 | H25: resident | I25: S02 | J25: B_转载待官方核 | K25: 归档状态与SHA-256见source_snapshot_manifest.csv；口径核实见source_number_audit.csv | M25: 征缴基金，不等于同一县域待遇支付的全部资金来源 | N25: S02
A26: 360823 | B26: 峡江县 | C26: 县 | D26: 2024 | E26: resident_population_year_end | F26: 146153 | G26: 人 | H26: 常住人口 | I26: S03 | J26: B_转载待官方核 | K26: 归档状态与SHA-256见source_snapshot_manifest.csv；口径核实见source_number_audit.csv | N26: S03
A27: 360823 | B27: 峡江县 | C27: 县 | D27: 2024 | E27: births | F27: 1188 | G27: 人 | H27: 常住人口 | I27: S03 | J27: B_转载待官方核 | K27: 归档状态与SHA-256见source_snapshot_manifest.csv；口径核实见source_number_audit.csv | N27: S03
A28: 360823 | B28: 峡江县 | C28: 县 | D28: 2024 | E28: deaths | F28: 1251 | G28: 人 | H28: 常住人口 | I28: S03 | J28: B_转载待官方核 | K28: 归档状态与SHA-256见source_snapshot_manifest.csv；口径核实见source_number_audit.csv | N28: S03
A29: 360823 | B29: 峡江县 | C29: 县 | D29: 2024 | E29: urban_resident_population | F29: 77415 | G29: 人 | H29: 常住人口 | I29: S03 | J29: B_转载待官方核 | K29: 归档状态与SHA-256见source_snapshot_manifest.csv；口径核实见source_number_audit.csv | N29: S03
A30: 360823 | B30: 峡江县 | C30: 县 | D30: 2024 | E30: hukou_population | F30: 188734 | G30: 人 | H30: 户籍 | I30: S03 | J30: B_转载待官方核 | K30: 归档状态与SHA-256见source_snapshot_manifest.csv；口径核实见source_number_audit.csv | N30: S03
A31: 360823 | B31: 峡江县 | C31: 县 | D31: 2025 | E31: resident_population_year_end | F31: 142688 | G31: 人 | H31: 常住人口 | I31: S02 | J31: B_转载待官方核 | K31: 归档状态与SHA-256见source_snapshot_manifest.csv；口径核实见source_number_audit.csv | N31: S02
A32: 360823 | B32: 峡江县 | C32: 县 | D32: 2025 | E32: births | F32: 931 | G32: 人 | H32: 常住人口 | I32: S02 | J32: B_转载待官方核 | K32: 归档状态与SHA-256见source_snapshot_manifest.csv；口径核实见source_number_audit.csv | N32: S02
A33: 360823 | B33: 峡江县 | C33: 县 | D33: 2025 | E33: deaths | F33: 1048 | G33: 人 | H33: 常住人口 | I33: S02 | J33: B_转载待官方核 | K33: 归档状态与SHA-256见source_snapshot_manifest.csv；口径核实见source_number_audit.csv | N33: S02
A34: 360823 | B34: 峡江县 | C34: 县 | D34: 2025 | E34: urban_resident_population | F34: 76554 | G34: 人 | H34: 常住人口 | I34: S02 | J34: B_转载待官方核 | K34: 归档状态与SHA-256见source_snapshot_manifest.csv；口径核实见source_number_audit.csv | N34: S02
A35: 360823 | B35: 峡江县 | C35: 县 | D35: 2025 | E35: hukou_population | F35: 187997 | G35: 人 | H35: 户籍 | I35: S02 | J35: B_转载待官方核 | K35: 归档状态与SHA-256见source_snapshot_manifest.csv；口径核实见source_number_audit.csv | N35: S02
A36: 360821 | B36: 吉安县 | C36: 县 | D36: 2025 | E36: pension_enterprise_annual_paid | F36: 57981 | G36: 万元 | H36: enterprise | I36: S04 | J36: B_转载待官方核 | K36: 归档状态与SHA-256见source_snapshot_manifest.csv；口径核实见source_number_audit.csv | M36: 不能用参保人数替代待遇人数 | N36: S04
A37: 360821 | B37: 吉安县 | C37: 县 | D37: 2025 | E37: pension_public_annual_paid | F37: 32639 | G37: 万元 | H37: public | I37: S04 | J37: B_转载待官方核 | K37: 归档状态与SHA-256见source_snapshot_manifest.csv；口径核实见source_number_audit.csv | M37: 不能用参保人数替代待遇人数 | N37: S04
A38: 360821 | B38: 吉安县 | C38: 县 | D38: 2025 | E38: pension_resident_annual_paid | F38: 22880 | G38: 万元 | H38: resident | I38: S04 | J38: B_转载待官方核 | K38: 归档状态与SHA-256见source_snapshot_manifest.csv；口径核实见source_number_audit.csv | M38: 不能用参保人数替代待遇人数 | N38: S04
A39: 360821 | B39: 吉安县 | C39: 县 | D39: 2025 | E39: new_urban_jobs | F39: 6041 | G39: 人 | I39: S04 | J39: B_转载待官方核 | K39: 归档状态与SHA-256见source_snapshot_manifest.csv；口径核实见source_number_audit.csv | N39: S04
A40: 360821 | B40: 吉安县 | C40: 县 | D40: 2025 | E40: urban_income | F40: 46935 | G40: 元 | I40: S04 | J40: B_转载待官方核 | K40: 归档状态与SHA-256见source_snapshot_manifest.csv；口径核实见source_number_audit.csv | N40: S04
A41: 360821 | B41: 吉安县 | C41: 县 | D41: 2025 | E41: rural_income | F41: 21265 | G41: 元 | I41: S04 | J41: B_转载待官方核 | K41: 归档状态与SHA-256见source_snapshot_manifest.csv；口径核实见source_number_audit.csv | N41: S04
A42: 360735 | B42: 石城县 | C42: 县 | D42: 2025 | E42: resident_population_year_end | F42: 280500 | G42: 人 | H42: 常住 | I42: S07 | J42: A_政府原文 | K42: 归档状态与SHA-256见source_snapshot_manifest.csv；口径核实见source_number_audit.csv | N42: S07
A43: 360735 | B43: 石城县 | C43: 县 | D43: 2025 | E43: hukou_population | F43: 327427 | G43: 人 | H43: 户籍 | I43: S07 | J43: A_政府原文 | K43: 归档状态与SHA-256见source_snapshot_manifest.csv；口径核实见source_number_audit.csv | N43: S07
A44: 360735 | B44: 石城县 | C44: 县 | D44: 2025 | E44: hukou_age_60plus | F44: 61421 | G44: 人 | H44: 户籍 | I44: S07 | J44: A_政府原文 | K44: 归档状态与SHA-256见source_snapshot_manifest.csv；口径核实见source_number_audit.csv | N44: S07
A45: 360735 | B45: 石城县 | C45: 县 | D45: 2025 | E45: new_urban_jobs | F45: 1410 | G45: 人 | I45: S07 | J45: A_政府原文 | K45: 归档状态与SHA-256见source_snapshot_manifest.csv；口径核实见source_number_audit.csv | N45: S07
A46: 360735 | B46: 石城县 | C46: 县 | D46: 2025 | E46: urban_income | F46: 37550 | G46: 元 | H46: 城镇居民 | I46: S07 | J46: A_政府原文 | K46: 归档状态与SHA-256见source_snapshot_manifest.csv；口径核实见source_number_audit.csv | N46: S07
A47: 360735 | B47: 石城县 | C47: 县 | D47: 2025 | E47: rural_income | F47: 19075 | G47: 元 | H47: 农村居民 | I47: S07 | J47: A_政府原文 | K47: 归档状态与SHA-256见source_snapshot_manifest.csv；口径核实见source_number_audit.csv | N47: S07
A48: 360735 | B48: 石城县 | C48: 县 | D48: 2025 | E48: general_public_budget_income | F48: 85425 | G48: 万元 | H48: 一般公共预算 | I48: S07 | J48: A_政府原文 | K48: 归档状态与SHA-256见source_snapshot_manifest.csv；口径核实见source_number_audit.csv | N48: S07
A49: 360735 | B49: 石城县 | C49: 县 | D49: 2025 | E49: general_public_budget_expenditure | F49: 295697 | G49: 万元 | H49: 一般公共预算 | I49: S07 | J49: A_政府原文 | K49: 归档状态与SHA-256见source_snapshot_manifest.csv；口径核实见source_number_audit.csv | N49: S07
A50: 360735 | B50: 石城县 | C50: 县 | D50: 2025 | E50: gdp | F50: 120.7736 | G50: 亿元 | I50: S07 | J50: A_政府原文 | K50: 归档状态与SHA-256见source_snapshot_manifest.csv；口径核实见source_number_audit.csv | N50: S07
A51: 360702 | B51: 章贡区 | C51: 县 | D51: 2024 | E51: resident_population_year_end | F51: 715200 | G51: 人 | H51: 常住 | I51: S06 | J51: A_政府原文 | K51: 归档状态与SHA-256见source_snapshot_manifest.csv；口径核实见source_number_audit.csv | M51: 表内原单位万人，精度0.01万人 | N51: S06
...

Sheet 逐条来源审计
A1: region_code | B1: year | C1: indicator_id | D1: population_scope | E1: source_id | F1: registered_value | G1: source_value_or_token | H1: audit_result | I1: source_locator | J1: snapshot_sha256
A2: 360823 | B2: 2024 | C2: pension_enterprise_recipients_year_end | D2: enterprise | E2: S03 | F2: 10779 | G2: 10779 | H2: numeric_token_present | I2: HTML text / character 4509 | J2: 5a7b217e14a5e5cd78ad5fe84bdcbc95e4e865e5a4dcbf032c4b6e0ebafcab42
A3: 360823 | B3: 2024 | C3: pension_enterprise_annual_paid | D3: enterprise | E3: S03 | F3: 26955.46 | G3: 26955.46 | H3: numeric_token_present | I3: HTML text / character 4521 | J3: 5a7b217e14a5e5cd78ad5fe84bdcbc95e4e865e5a4dcbf032c4b6e0ebafcab42
A4: 360823 | B4: 2024 | C4: pension_enterprise_active_or_paid | D4: enterprise | E4: S03 | F4: 24495 | G4: 24495 | H4: numeric_token_present | I4: HTML text / character 4484 | J4: 5a7b217e14a5e5cd78ad5fe84bdcbc95e4e865e5a4dcbf032c4b6e0ebafcab42
A5: 360823 | B5: 2024 | C5: pension_enterprise_contribution | D5: enterprise | E5: S03 | F5: 18642.9 | G5: 18642.9 | H5: numeric_token_present | I5: HTML text / character 4494 | J5: 5a7b217e14a5e5cd78ad5fe84bdcbc95e4e865e5a4dcbf032c4b6e0ebafcab42
A6: 360823 | B6: 2024 | C6: pension_public_recipients_year_end | D6: public | E6: S03 | F6: 2453 | G6: 2453 | H6: numeric_token_present | I6: HTML text / character 4585 | J6: 5a7b217e14a5e5cd78ad5fe84bdcbc95e4e865e5a4dcbf032c4b6e0ebafcab42
A7: 360823 | B7: 2024 | C7: pension_public_annual_paid | D7: public | E7: S03 | F7: 15209.48 | G7: 15209.48 | H7: numeric_token_present | I7: HTML text / character 4596 | J7: 5a7b217e14a5e5cd78ad5fe84bdcbc95e4e865e5a4dcbf032c4b6e0ebafcab42
A8: 360823 | B8: 2024 | C8: pension_public_active_or_paid | D8: public | E8: S03 | F8: 4977 | G8: 4977 | H8: numeric_token_present | I8: HTML text / character 4561 | J8: 5a7b217e14a5e5cd78ad5fe84bdcbc95e4e865e5a4dcbf032c4b6e0ebafcab42
A9: 360823 | B9: 2024 | C9: pension_public_contribution | D9: public | E9: S03 | F9: 11378.18 | G9: 11378.18 | H9: numeric_token_present | I9: HTML text / character 4570 | J9: 5a7b217e14a5e5cd78ad5fe84bdcbc95e4e865e5a4dcbf032c4b6e0ebafcab42
A10: 360823 | B10: 2024 | C10: pension_resident_recipients_year_end | D10: resident | E10: S03 | F10: 25995 | G10: 25995 | H10: numeric_token_present | I10: HTML text / character 4669 | J10: 5a7b217e14a5e5cd78ad5fe84bdcbc95e4e865e5a4dcbf032c4b6e0ebafcab42
A11: 360823 | B11: 2024 | C11: pension_resident_annual_paid | D11: resident | E11: S03 | F11: 5975.44 | G11: 5975.44 | H11: numeric_token_present | I11: HTML text / character 4680 | J11: 5a7b217e14a5e5cd78ad5fe84bdcbc95e4e865e5a4dcbf032c4b6e0ebafcab42
A12: 360823 | B12: 2024 | C12: pension_resident_active_or_paid | D12: resident | E12: S03 | F12: 33989 | G12: 33989 | H12: numeric_token_present | I12: HTML text / character 4643 | J12: 5a7b217e14a5e5cd78ad5fe84bdcbc95e4e865e5a4dcbf032c4b6e0ebafcab42
... A38: 360821 | B38: 2025 | C38: pension_resident_annual_paid | D38: resident | E38: S04 | F38: 22880 | G38: 22880 | H38: numeric_token_present | I38: HTML text / character 5790 | J38: 0b098126f1d4f8d966f8ab47d99d5f1f7577a475b5f222d3390bf61176c32b01
A39: 360821 | B39: 2025 | C39: new_urban_jobs | E39: S04 | F39: 6041 | G39: 6041 | H39: numeric_token_present | I39: HTML text / character 5272 | J39: 0b098126f1d4f8d966f8ab47d99d5f1f7577a475b5f222d3390bf61176c32b01
A40: 360821 | B40: 2025 | C40: urban_income | E40: S04 | F40: 46935 | G40: 46935 | H40: numeric_token_present | I40: HTML text / character 5498 | J40: 0b098126f1d4f8d966f8ab47d99d5f1f7577a475b5f222d3390bf61176c32b01
A41: 360821 | B41: 2025 | C41: rural_income | E41: S04 | F41: 21265 | G41: 21265 | H41: numeric_token_present | I41: HTML text / character 5524 | J41: 0b098126f1d4f8d966f8ab47d99d5f1f7577a475b5f222d3390bf61176c32b01
A42: 360735 | B42: 2025 | C42: resident_population_year_end | D42: 常住 | E42: S07 | F42: 280500 | G42: 28.05 | H42: numeric_token_present | I42: HTML text / character 3208 | J42: a490422fd429eeb1dbc2450f4f14e1785ec940e8e920b6d54cb639fe23278ba6
A43: 360735 | B43: 2025 | C43: hukou_population | D43: 户籍 | E43: S07 | F43: 327427 | G43: 327427 | H43: numeric_token_present | I43: HTML text / character 3139 | J43: a490422fd429eeb1dbc2450f4f14e1785ec940e8e920b6d54cb639fe23278ba6
A44: 360735 | B44: 2025 | C44: hukou_age_60plus | D44: 户籍 | E44: S07 | F44: 61421 | G44: 61421 | H44: numeric_token_present | I44: HTML text / character 3170 | J44: a490422fd429eeb1dbc2450f4f14e1785ec940e8e920b6d54cb639fe23278ba6
A45: 360735 | B45: 2025 | C45: new_urban_jobs | E45: S07 | F45: 1410 | G45: 1410 | H45: numeric_token_present | I45: HTML text / character 3473 | J45: a490422fd429eeb1dbc2450f4f14e1785ec940e8e920b6d54cb639fe23278ba6
A46: 360735 | B46: 2025 | C46: urban_income | D46: 城镇居民 | E46: S07 | F46: 37550 | G46: 37550 | H46: numeric_token_present | I46: HTML text / character 3385 | J46: a490422fd429eeb1dbc2450f4f14e1785ec940e8e920b6d54cb639fe23278ba6
A47: 360735 | B47: 2025 | C47: rural_income | D47: 农村居民 | E47: S07 | F47: 19075 | G47: 19075 | H47: numeric_token_present | I47: HTML text / character 3406 | J47: a490422fd429eeb1dbc2450f4f14e1785ec940e8e920b6d54cb639fe23278ba6
A48: 360735 | B48: 2025 | C48: general_public_budget_income | D48: 一般公共预算 | E48: S07 | F48: 85425 | G48: 85425 | H48: numeric_token_present | I48: HTML text / character 792 | J48: a490422fd429eeb1dbc2450f4f14e1785ec940e8e920b6d54cb639fe23278ba6
A49: 360735 | B49: 2025 | C49: general_public_budget_expenditure | D49: 一般公共预算 | E49: S07 | F49: 295697 | G49: 295697 | H49: numeric_token_present | I49: HTML text / character 864 | J49: a490422fd429eeb1dbc2450f4f14e1785ec940e8e920b6d54cb639fe23278ba6
A50: 360735 | B50: 2025 | C50: gdp | E50: S07 | F50: 120.7736 | G50: 1207736 | H50: numeric_token_present | I50: HTML text / character 571 | J50: a490422fd429eeb1dbc2450f4f14e1785ec940e8e920b6d54cb639fe23278ba6
A51: 360702 | B51: 2024 | C51: resident_population_year_end | D51: 常住 | E51: S06 | F51: 715200 | G51: 71.52 | H51: table_cell_match | I51: HTML table / 章贡区 / column 2 | J51: a6be1e1c39cedd3e71867cc93f3948b44b942055e9836114124acc95ff037289
A52: 360702 | B52: 2024 | C52: urbanization_rate | D52: 常住 | E52: S06 | F52: 90.95 | G52: 90.95 | H52: table_cell_match | I52: HTML table / 章贡区 / column 4 | J52: a6be1e1c39cedd3e71867cc93f3948b44b942055e9836114124acc95ff037289
A53: 360702 | B53: 2025 | C53: resident_population_year_end | D53: 常住 | E53: S05 | F53: 718000 | G53: 71.80 | H53: table_cell_match | I53: HTML table / 章贡区 / column 2 | J53: d946a7a33e097676c1722dbead1b8f957b9138701f496b6d3e006a820f64420a
A54: 360702 | B54: 2025 | C54: urbanization_rate | D54: 常住 | E54: S05 | F54: 91.47 | G54: 91.47 | H54: table_cell_match | I54: HTML table / 章贡区 / column 4 | J54: d946a7a33e097676c1722dbead1b8f957b9138701f496b6d3e006a820f64420a
A55: 360703 | B55: 2024 | C55: resident_population_year_end | D55: 常住 | E55: S06 | F55: 835200 | G55: 83.52 | H55: table_cell_match | I55: HTML table / 南康区 / column 2 | J55: a6be1e1c39cedd3e71867cc93f3948b44b942055e9836114124acc95ff037289
A56: 360703 | B56: 2024 | C56: urbanization_rate | D56: 常住 | E56: S06 | F56: 62.99 | G56: 62.99 | H56: table_cell_match | I56: HTML table / 南康区 / column 4 | J56: a6be1e1c39cedd3e71867cc93f3948b44b942055e9836114124acc95ff037289
A57: 360703 | B57: 2025 | C57: resident_population_year_end | D57: 常住 | E57: S05 | F57: 838200 | G57: 83.82 | H57: table_cell_match | I57: HTML table / 南康区 / column 2 | J57: d946a7a33e097676c1722dbead1b8f957b9138701f496b6d3e006a820f64420a
A58: 360703 | B58: 2025 | C58: urbanization_rate | D58: 常住 | E58: S05 | F58: 64.61 | G58: 64.61 | H58: table_cell_match | I58: HTML table / 南康区 / column 4 | J58: d946a7a33e097676c1722dbead1b8f957b9138701f496b6d3e006a820f64420a
A59: 360704 | B59: 2024 | C59: resident_population_year_end | D59: 常住 | E59: S06 | F59: 575900 | G59: 57.59 | H59: table_cell_match | I59: HTML table / 赣县区 / column 2 | J59: a6be1e1c39cedd3e71867cc93f3948b44b942055e9836114124acc95ff037289
A60: 360704 | B60: 2024 | C60: urbanization_rate | D60: 常住 | E60: S06 | F60: 57.24 | G60: 57.24 | H60: table_cell_match | I60: HTML table / 赣县区 / column 4 | J60: a6be1e1c39cedd3e71867cc93f3948b44b942055e9836114124acc95ff037289
A61: 360704 | B61: 2025 | C61: resident_population_year_end | D61: 常住 | E61: S05 | F61: 573400 | G61: 57.34 | H61: table_cell_match | I61: HTML table / 赣县区 / column 2 | J61: d946a7a33e097676c1722dbead1b8f957b9138701f496b6d3e006a820f64420a
A62: 360704 | B62: 2025 | C62: urbanization_rate | D62: 常住 | E62: S05 | F62: 58.48 | G62: 58.48 | H62: table_cell_match | I62: HTML table / 赣县区 / column 4 | J62: d946a7a33e097676c1722dbead1b8f957b9138701f496b6d3e006a820f64420a
... A130: 360000 | B130: 2025 | C130: gdp | D130: 全省 | E130: S01 | F130: 36020 | G130: 36020 | H130: numeric_token_present | I130: HTML text / character 376 | J130: c66c9d5bf22e6369074d3d5433fbe08111b6cade7fadeba6e3d511279ed348cc
A131: 360000 | B131: 2024 | C131: resident_population_year_end | D131: 全省 | E131: S01 | F131: 45020000 | H131: derived_not_literal | J131: c66c9d5bf22e6369074d3d5433fbe08111b6cade7fadeba6e3d511279ed348cc
A132: 360000 | B132: 2025 | C132: provident_contributors | D132: 全省 | E132: S08 | F132: 3537700 | H132: snapshot_unavailable
...

Sheet 指标口径
A1: indicator_id | B1: 定义与限制 | C1: 是否完整终核
A2: births | B2: 当年出生人口；自然变动=出生-死亡 | C2: 按来源限定
A3: deaths | B3: 当年死亡人口 | C3: 按来源限定
A4: gdp | B4: 详见来源公报及事实备注；尚未形成统一统计定义 | C4: 否
A5: general_public_budget_expenditure | B5: 详见来源公报及事实备注；尚未形成统一统计定义 | C5: 否
A6: general_public_budget_income | B6: 详见来源公报及事实备注；尚未形成统一统计定义 | C6: 否
A7: hukou_age_60plus | B7: 年末户籍60岁及以上人口，不可除以常住人口 | C7: 按来源限定
A8: hukou_population | B8: 详见来源公报及事实备注；尚未形成统一统计定义 | C8: 否
A9: new_urban_jobs | B9: 详见来源公报及事实备注；尚未形成统一统计定义 | C9: 否
A10: pension_employee_enrolled | B10: 详见来源公报及事实备注；尚未形成统一统计定义 | C10: 否
A11: pension_enterprise_active_or_paid | B11: 在职参保或居民实际缴费人数；两者不同口径 | C11: 按来源限定
A12: pension_enterprise_annual_paid | B12: 全年发放养老金金额；公报口径待与经办机构核对 | C12: 按来源限定
... A40: urbanization_rate | B40: 年末常住人口城镇化率，百分数 | C40: 按来源限定

Sheet 峡江养老金复算
A1: 年份 | B1: 制度 | C1: 年末领取人数 | D1: 年度发放万元 | E1: 人数占比 | F1: 金额占比 | G1: 月均金额代理元 | H1: 来源 | I1: 证据等级
A2: 2024 | B2: 企业职工 | C2: 10779 | D2: 26955.46 | E2: =C2/SUM(C$2:C$4) | F2: =D2/SUM(D$2:D$4) | G2: =D2*10000/C2/12 | H2: S03 | I2: B_转载待官方原件
A3: 2024 | B3: 机关事业 | C3: 2453 | D3: 15209.48 | E3: =C3/SUM(C$2:C$4) | F3: =D3/SUM(D$2:D$4) | G3: =D3*10000/C3/12 | H3: S03 | I3: B_转载待官方原件
A4: 2024 | B4: 城乡居民 | C4: 25995 | D4: 5975.44 | E4: =C4/SUM(C$2:C$4) | F4: =D4/SUM(D$2:D$4) | G4: =D4*10000/C4/12 | H4: S03 | I4: B_转载待官方原件
A5: 2025 | B5: 企业职工 | C5: 11273 | D5: 29571.25 | E5: =C5/SUM(C$5:C$7) | F5: =D5/SUM(D$5:D$7) | G5: =D5*10000/C5/12 | H5: S02 | I5: B_转载待官方原件
A6: 2025 | B6: 机关事业 | C6: 2508 | D6: 16218.5 | E6: =C6/SUM(C$5:C$7) | F6: =D6/SUM(D$5:D$7) | G6: =D6*10000/C6/12 | H6: S02 | I6: B_转载待官方原件
A7: 2025 | B7: 城乡居民 | C7: 27367 | D7: 7910.83 | E7: =C7/SUM(C$5:C$7) | F7: =D7/SUM(D$5:D$7) | G7: =D7*10000/C7/12 | H7: S02 | I7: B_转载待官方原件

Sheet 养老金金额分解
A1: 制度 | B1: 2024金额万元 | C1: 2025金额万元 | D1: 变化万元 | E1: 人数分量万元 | F1: 金额人均代理分量万元 | G1: 恒等误差 | H1: 解释
A2: 企业职工 | B2: ='峡江养老金复算'!D2 | C2: ='峡江养老金复算'!D5 | D2: =C2-B2 | E2: =('峡江养老金复算'!C5-'峡江养老金复算'!C2)*(B2/'峡江养老金复算'!C2+C2/'峡江养老金复算'!C5)/2 | F2: =(C2/'峡江养老金复算'!C5-B2/'峡江养老金复算'!C2)*('峡江养老金复算'!C2+'峡江养老金复算'!C5)/2 | G2: =D2-E2-F2 | H2: 对称分解；年末人数代理；非因果效应
A3: 机关事业 | B3: ='峡江养老金复算'!D3 | C3: ='峡江养老金复算'!D6 | D3: =C3-B3 | E3: =('峡江养老金复算'!C6-'峡江养老金复算'!C3)*(B3/'峡江养老金复算'!C3+C3/'峡江养老金复算'!C6)/2 | F3: =(C3/'峡江养老金复算'!C6-B3/'峡江养老金复算'!C3)*('峡江养老金复算'!C3+'峡江养老金复算'!C6)/2 | G3: =D3-E3-F3 | H3: 对称分解；年末人数代理；非因果效应
A4: 城乡居民 | B4: ='峡江养老金复算'!D4 | C4: ='峡江养老金复算'!D7 | D4: =C4-B4 | E4: =('峡江养老金复算'!C7-'峡江养老金复算'!C4)*(B4/'峡江养老金复算'!C4+C4/'峡江养老金复算'!C7)/2 | F4: =(C4/'峡江养老金复算'!C7-B4/'峡江养老金复算'!C4)*('峡江养老金复算'!C4+'峡江养老金复算'!C7)/2 | G4: =D4-E4-F4 | H4: 对称分解；年末人数代理；非因果效应

Sheet 赣州18县人口
A1: 行政代码 | B1: 县区 | C1: 2024常住人口人 | D1: 2025常住人口人 | E1: 人口变化人 | F1: 2024城镇化率% | G1: 2025城镇化率% | H1: 城镇化变化百分点 | I1: 证据
A2: 360702 | B2: 章贡区 | C2: 715200 | D2: 718000 | E2: =D2-C2 | F2: 90.95 | G2: 91.47 | H2: =G2-F2 | I2: S06/S05政府表格单元格复核
A3: 360703 | B3: 南康区 | C3: 835200 | D3: 838200 | E3: =D3-C3 | F3: 62.99 | G3: 64.61 | H3: =G3-F3 | I3: S06/S05政府表格单元格复核
A4: 360704 | B4: 赣县区 | C4: 575900 | D4: 573400 | E4: =D4-C4 | F4: 57.24 | G4: 58.48 | H4: =G4-F4 | I4: S06/S05政府表格单元格复核
A5: 360781 | B5: 瑞金市 | C5: 610600 | D5: 606700 | E5: =D5-C5 | F5: 53.69 | G5: 55.13 | H5: =G5-F5 | I5: S06/S05政府表格单元格复核
A6: 360783 | B6: 龙南市 | C6: 316300 | D6: 316700 | E6: =D6-C6 | F6: 67.78 | G6: 68.87 | H6: =G6-F6 | I6: S06/S05政府表格单元格复核
A7: 360722 | B7: 信丰县 | C7: 672300 | D7: 672400 | E7: =D7-C7 | F7: 56.01 | G7: 57.52 | H7: =G7-F7 | I7: S06/S05政府表格单元格复核
A8: 360723 | B8: 大余县 | C8: 261300 | D8: 260700 | E8: =D8-C8 | F8: 57.04 | G8: 58.48 | H8: =G8-F8 | I8: S06/S05政府表格单元格复核
A9: 360724 | B9: 上犹县 | C9: 266900 | D9: 265700 | E9: =D9-C9 | F9: 51.97 | G9: 53.44 | H9: =G9-F9 | I9: S06/S05政府表格单元格复核
A10: 360725 | B10: 崇义县 | C10: 176300 | D10: 175700 | E10: =D10-C10 | F10: 50.42 | G10: 51.79 | H10: =G10-F10 | I10: S06/S05政府表格单元格复核
A11: 360726 | B11: 安远县 | C11: 343300 | D11: 342200 | E11: =D11-C11 | F11: 49.92 | G11: 51.51 | H11: =G11-F11 | I11: S06/S05政府表格单元格复核
A12: 360728 | B12: 定南县 | C12: 208500 | D12: 209700 | E12: =D12-C12 | F12: 66.9 | G12: 68.13 | H12: =G12-F12 | I12: S06/S05政府表格单元格复核
A13: 360729 | B13: 全南县 | C13: 168100 | D13: 168000 | E13: =D13-C13 | F13: 58.16 | G13: 59.53 | H13: =G13-F13 | I13: S06/S05政府表格单元格复核
... A19: 360735 | B19: 石城县 | C19: 281200 | D19: 280500 | E19: =D19-C19 | F19: 51.76 | G19: 53.34 | H19: =G19-F19 | I19: S06/S05政府表格单元格复核

Sheet 县级覆盖与缺失
A1: 年份 | B1: 指标 | C1: 有值县数 | D1: 缺失县数 | E1: 缺失率 | F1: 主要原因
A2: 2024 | B2: resident_population_year_end | C2: 19 | D2: 81 | E2: 0.81 | F2: 公开来源未采得可核县级同口径值；空值不表示0
A3: 2024 | B3: urbanization_rate | C3: 18 | D3: 82 | E3: 0.82 | F3: 公开来源未采得可核县级同口径值；空值不表示0
A4: 2024 | B4: pension_enterprise_annual_paid | C4: 1 | D4: 99 | E4: 0.99 | F4: 公开来源未采得可核县级同口径值；空值不表示0
A5: 2024 | B5: pension_public_annual_paid | C5: 1 | D5: 99 | E5: 0.99 | F5: 公开来源未采得可核县级同口径值；空值不表示0
A6: 2024 | B6: pension_resident_annual_paid | C6: 1 | D6: 99 | E6: 0.99 | F6: 公开来源未采得可核县级同口径值；空值不表示0
A7: 2024 | B7: pension_enterprise_recipients_year_end | C7: 1 | D7: 99 | E7: 0.99 | F7: 公开来源未采得可核县级同口径值；空值不表示0
A8: 2024 | B8: pension_public_recipients_year_end | C8: 1 | D8: 99 | E8: 0.99 | F8: 公开来源未采得可核县级同口径值；空值不表示0
A9: 2024 | B9: pension_resident_recipients_year_end | C9: 1 | D9: 99 | E9: 0.99 | F9: 公开来源未采得可核县级同口径值；空值不表示0
A10: 2024 | B10: provident_contributors | C10: 0 | D10: 100 | E10: 1 | F10: 公开来源未采得可核县级同口径值；空值不表示0
A11: 2025 | B11: resident_population_year_end | C11: 20 | D11: 80 | E11: 0.8 | F11: 公开来源未采得可核县级同口径值；空值不表示0
A12: 2025 | B12: urbanization_rate | C12: 18 | D12: 82 | E12: 0.82 | F12: 公开来源未采得可核县级同口径值；空值不表示0
A13: 2025 | B13: pension_enterprise_annual_paid | C13: 2 | D13: 98 | E13: 0.98 | F13: 公开来源未采得可核县级同口径值；空值不表示0
... A19: 2025 | B19: provident_contributors | C19: 0 | D19: 100 | E19: 1 | F19: 公开来源未采得可核县级同口径值；空值不表示0
